Last login: Mon Apr 11 10:31:05 on console
pavel@iMac-Pavel ~ % cd /Users/pavel/Desktop/Программирование/spam-bot
pavel@iMac-Pavel spam-bot % git pull
hint: Pulling without specifying how to reconcile divergent branches is
hint: discouraged. You can squelch this message by running one of the following
hint: commands sometime before your next pull:
hint: 
hint:   git config pull.rebase false  # merge (the default strategy)
hint:   git config pull.rebase true   # rebase
hint:   git config pull.ff only       # fast-forward only
hint: 
hint: You can replace "git config" with "git config --global" to set a default
hint: preference for all repositories. You can also pass --rebase, --no-rebase,
hint: or --ff-only on the command line to override the configured default per
hint: invocation.
Enter passphrase for key '/Users/pavel/.ssh/id_rsa': 
git@github.com: Permission denied (publickey).
fatal: Could not read from remote repository.

Please make sure you have the correct access rights
and the repository exists.
pavel@iMac-Pavel spam-bot % git pull
hint: Pulling without specifying how to reconcile divergent branches is
hint: discouraged. You can squelch this message by running one of the following
hint: commands sometime before your next pull:
hint: 
hint:   git config pull.rebase false  # merge (the default strategy)
hint:   git config pull.rebase true   # rebase
hint:   git config pull.ff only       # fast-forward only
hint: 
hint: You can replace "git config" with "git config --global" to set a default
hint: preference for all repositories. You can also pass --rebase, --no-rebase,
hint: or --ff-only on the command line to override the configured default per
hint: invocation.
Enter passphrase for key '/Users/pavel/.ssh/id_rsa': 
Enter passphrase for key '/Users/pavel/.ssh/id_rsa': 
remote: Enumerating objects: 44, done.
remote: Counting objects: 100% (44/44), done.
remote: Compressing objects: 100% (19/19), done.
remote: Total 34 (delta 19), reused 30 (delta 15), pack-reused 0
Unpacking objects: 100% (34/34), 11.18 KiB | 104.00 KiB/s, done.
From github.com:PavelG1307/spam-bot
   c58e6e3..404c505  master     -> origin/master
Updating c58e6e3..404c505
Fast-forward
 .DS_Store                                          |   Bin 6148 -> 10244 bytes
 __pycache__/account.cpython-38.pyc                 |   Bin 0 -> 1375 bytes
 account.py                                         |    28 +-
 account0.session                                   |   Bin 28672 -> 28672 bytes
 accounts.ini                                       |     2 +-
 bot.session                                        |   Bin 28672 -> 28672 bytes
 bot.session-journal                                |   Bin 0 -> 16928 bytes
 chats/.DS_Store                                    |   Bin 0 -> 6148 bytes
 chats/2.txt                                        |    90 -
 chats/dsfhjhasfjh.txt                              | 17450 +++++++++++++++++++
 config.ini                                         |     4 +-
 main.py                                            |   258 +-
 .../.DS_Store"                                     |   Bin 0 -> 6148 bytes
 .../account0.session"                              |   Bin 0 -> 28672 bytes
 .../accounts.ini"                                  |     1 +
 .../config.ini"                                    |     3 +
 16 files changed, 17684 insertions(+), 152 deletions(-)
 create mode 100644 __pycache__/account.cpython-38.pyc
 create mode 100644 bot.session-journal
 create mode 100644 chats/.DS_Store
 create mode 100644 chats/dsfhjhasfjh.txt
 create mode 100644 "\320\227\320\260\320\261\320\260\320\275\320\265\320\275\320\275\321\213\320\271 \320\260\320\272\320\272/.DS_Store"
 create mode 100644 "\320\227\320\260\320\261\320\260\320\275\320\265\320\275\320\275\321\213\320\271 \320\260\320\272\320\272/account0.session"
 create mode 100644 "\320\227\320\260\320\261\320\260\320\275\320\265\320\275\320\275\321\213\320\271 \320\260\320\272\320\272/accounts.ini"
 create mode 100644 "\320\227\320\260\320\261\320\260\320\275\320\265\320\275\320\275\321\213\320\271 \320\260\320\272\320\272/config.ini"
pavel@iMac-Pavel spam-bot % python3 main.py
chats
В работе 1 аккаунтов
ID бота: 5140545419
Аккаунт 0 запущен
['dsfhjhasfjh']
Всего чатов 17450
/select_account
[[1002363042], [-1]]
/bot_dsfhjhasfjh
[[1002363042], [0]]
^C
pavel@iMac-Pavel spam-bot % 
pavel@iMac-Pavel spam-bot % python3 main.py
chats
В работе 1 аккаунтов
ID бота: 5140545419
Аккаунт 0 запущен
['dsfhjhasfjh']
Всего чатов 17450
/select_account
[[1002363042], [-1]]
/bot_dsfhjhasfjh
__init__() got an unexpected keyword argument 'resize'
Traceback (most recent call last):
  File "/Users/pavel/Library/Python/3.8/lib/python/site-packages/pyrogram/dispatcher.py", line 222, in handler_worker
    await handler.callback(self.client, *args)
  File "main.py", line 300, in bot_handl
    await message.reply('Выбран аккаунт: ' + username_acc[n], reply_markup=ReplyKeyboardMarkup([[KeyboardButton('/status'), KeyboardButton('/help'), KeyboardButton('/start_spam')]], resize = True))
TypeError: __init__() got an unexpected keyword argument 'resize'
^C%                                                                             pavel@iMac-Pavel spam-bot % python3 main.py
chats
В работе 1 аккаунтов
ID бота: 5140545419
Аккаунт 0 запущен
['dsfhjhasfjh']
Всего чатов 17450
/select_account
[[1002363042], [-1]]
/bot_dsfhjhasfjh
[[1002363042], [0]]
/status
/help
/select_account
/bot_dsfhjhasfjh
[[1002363042], [0]]
^C%                                                                             pavel@iMac-Pavel spam-bot % python3 main.py
  File "main.py", line 42
    with open('./accounts.ini'), 'r', encoding='utf-8') as fp:
                                              ^
SyntaxError: invalid syntax
pavel@iMac-Pavel spam-bot % python3 main.py
Traceback (most recent call last):
  File "main.py", line 456, in <module>
    ayncio.run(main())
NameError: name 'ayncio' is not defined
pavel@iMac-Pavel spam-bot % python3 main.py
chats
main.py:417: RuntimeWarning: coroutine 'open_from_file' was never awaited
  open_from_file()
RuntimeWarning: Enable tracemalloc to get the object allocation traceback
Traceback (most recent call last):
  File "main.py", line 456, in <module>
    asyncio.run(main())
  File "/Library/Developer/CommandLineTools/Library/Frameworks/Python3.framework/Versions/3.8/lib/python3.8/asyncio/runners.py", line 43, in run
    return loop.run_until_complete(main)
  File "/Library/Developer/CommandLineTools/Library/Frameworks/Python3.framework/Versions/3.8/lib/python3.8/asyncio/base_events.py", line 616, in run_until_complete
    return future.result()
  File "main.py", line 418, in main
    bot.add_handler(MessageHandler(bot_handl))
NameError: name 'bot' is not defined
pavel@iMac-Pavel spam-bot % python3 main.py
chats
main.py:417: RuntimeWarning: coroutine 'open_from_file' was never awaited
  open_from_file()
RuntimeWarning: Enable tracemalloc to get the object allocation traceback
Traceback (most recent call last):
  File "main.py", line 456, in <module>
    asyncio.run(main())
  File "/Library/Developer/CommandLineTools/Library/Frameworks/Python3.framework/Versions/3.8/lib/python3.8/asyncio/runners.py", line 43, in run
    return loop.run_until_complete(main)
  File "/Library/Developer/CommandLineTools/Library/Frameworks/Python3.framework/Versions/3.8/lib/python3.8/asyncio/base_events.py", line 616, in run_until_complete
    return future.result()
  File "main.py", line 418, in main
    bot.add_handler(MessageHandler(bot_handl))
NameError: name 'bot' is not defined
pavel@iMac-Pavel spam-bot % python3 main.py
chats
main.py:40: RuntimeWarning: coroutine 'resource_path' was never awaited
  with open(resource_path('./bot_tokken.ini'), 'r', encoding='utf-8') as fp:
RuntimeWarning: Enable tracemalloc to get the object allocation traceback
Traceback (most recent call last):
  File "main.py", line 456, in <module>
    asyncio.run(main())
  File "/Library/Developer/CommandLineTools/Library/Frameworks/Python3.framework/Versions/3.8/lib/python3.8/asyncio/runners.py", line 43, in run
    return loop.run_until_complete(main)
  File "/Library/Developer/CommandLineTools/Library/Frameworks/Python3.framework/Versions/3.8/lib/python3.8/asyncio/base_events.py", line 616, in run_until_complete
    return future.result()
  File "main.py", line 417, in main
    await open_from_file()
  File "main.py", line 40, in open_from_file
    with open(resource_path('./bot_tokken.ini'), 'r', encoding='utf-8') as fp:
TypeError: expected str, bytes or os.PathLike object, not coroutine
pavel@iMac-Pavel spam-bot % python3 main.py
chats
main.py:40: RuntimeWarning: coroutine 'resource_path' was never awaited
  with open(resource_path('./bot_tokken.ini'), 'r', encoding='utf-8') as fp:
RuntimeWarning: Enable tracemalloc to get the object allocation traceback
Traceback (most recent call last):
  File "main.py", line 456, in <module>
    asyncio.run(main())
  File "/Library/Developer/CommandLineTools/Library/Frameworks/Python3.framework/Versions/3.8/lib/python3.8/asyncio/runners.py", line 43, in run
    return loop.run_until_complete(main)
  File "/Library/Developer/CommandLineTools/Library/Frameworks/Python3.framework/Versions/3.8/lib/python3.8/asyncio/base_events.py", line 616, in run_until_complete
    return future.result()
  File "main.py", line 417, in main
    await open_from_file()
  File "main.py", line 40, in open_from_file
    with open(resource_path('./bot_tokken.ini'), 'r', encoding='utf-8') as fp:
TypeError: expected str, bytes or os.PathLike object, not coroutine
pavel@iMac-Pavel spam-bot % python3 main.py
chats
В работе 1 аккаунтов
Traceback (most recent call last):
  File "main.py", line 456, in <module>
    asyncio.run(main())
  File "/Library/Developer/CommandLineTools/Library/Frameworks/Python3.framework/Versions/3.8/lib/python3.8/asyncio/runners.py", line 43, in run
    return loop.run_until_complete(main)
  File "/Library/Developer/CommandLineTools/Library/Frameworks/Python3.framework/Versions/3.8/lib/python3.8/asyncio/base_events.py", line 616, in run_until_complete
    return future.result()
  File "main.py", line 418, in main
    await bot.add_handler(MessageHandler(bot_handl))
TypeError: object tuple can't be used in 'await' expression
pavel@iMac-Pavel spam-bot % python3 main.py
chats
В работе 1 аккаунтов
main.py:422: RuntimeWarning: coroutine 'GetMe.get_me' was never awaited
  print('ID бота:', bot.get_me().id)
RuntimeWarning: Enable tracemalloc to get the object allocation traceback
Traceback (most recent call last):
  File "main.py", line 456, in <module>
    asyncio.run(main())
  File "/Library/Developer/CommandLineTools/Library/Frameworks/Python3.framework/Versions/3.8/lib/python3.8/asyncio/runners.py", line 43, in run
    return loop.run_until_complete(main)
  File "/Library/Developer/CommandLineTools/Library/Frameworks/Python3.framework/Versions/3.8/lib/python3.8/asyncio/base_events.py", line 616, in run_until_complete
    return future.result()
  File "main.py", line 422, in main
    print('ID бота:', bot.get_me().id)
AttributeError: 'coroutine' object has no attribute 'id'
pavel@iMac-Pavel spam-bot % python3 main.py
chats
В работе 1 аккаунтов
ID бота: 5140545419
Аккаунт 0 запущен
['dsfhjhasfjh']
Всего чатов 17450
/select_account
[[1002363042], [-1]]
/bot_dsfhjhasfjh
[[1002363042], [0]]
/status
^C
pavel@iMac-Pavel spam-bot % 
pavel@iMac-Pavel spam-bot % python3 main.py
chats
В работе 1 аккаунтов
ID бота: 5140545419
Аккаунт 0 запущен
['dsfhjhasfjh']
Всего чатов 17450
/help
/status
[[1002363042], [-1]]
/select_account
/bot_dsfhjhasfjh
[[1002363042], [0]]
/set_spam_message
Hi! How did I end up here?
["Hello, I am promoting telegram channels and adding traffic from other people's channels! If you are interested, write in PM", 'Hi, if you need traffic to your Telegram channel, write in private messages!', 'Hi! How did I end up here?']
Who am I? Where am I?
["Hello, I am promoting telegram channels and adding traffic from other people's channels! If you are interested, write in PM", 'Hi, if you need traffic to your Telegram channel, write in private messages!', 'Hi! How did I end up here?', 'Who am I? Where am I?']
What's going on here?
["Hello, I am promoting telegram channels and adding traffic from other people's channels! If you are interested, write in PM", 'Hi, if you need traffic to your Telegram channel, write in private messages!', 'Hi! How did I end up here?', 'Who am I? Where am I?', "What's going on here?"]
What kind of chat?
["Hello, I am promoting telegram channels and adding traffic from other people's channels! If you are interested, write in PM", 'Hi, if you need traffic to your Telegram channel, write in private messages!', 'Hi! How did I end up here?', 'Who am I? Where am I?', "What's going on here?", 'What kind of chat?']
/save
Save message
main.py:70: RuntimeWarning: coroutine 'resource_path' was never awaited
  with open(resource_path('message.ini'), 'w', encoding='utf-8') as fp:
RuntimeWarning: Enable tracemalloc to get the object allocation traceback
expected str, bytes or os.PathLike object, not coroutine
Traceback (most recent call last):
  File "/Users/pavel/Library/Python/3.8/lib/python/site-packages/pyrogram/dispatcher.py", line 222, in handler_worker
    await handler.callback(self.client, *args)
  File "main.py", line 326, in bot_handl
    await Save("Message")
  File "main.py", line 70, in Save
    with open(resource_path('message.ini'), 'w', encoding='utf-8') as fp:
TypeError: expected str, bytes or os.PathLike object, not coroutine
^C
pavel@iMac-Pavel spam-bot % 
pavel@iMac-Pavel spam-bot % python3 main.py
  File "main.py", line 62
    with open('./accounts.ini'), 'w', encoding='utf-8') as fp:
                                              ^
SyntaxError: invalid syntax
pavel@iMac-Pavel spam-bot % python3 main.py
chats
В работе 1 аккаунтов
ID бота: 5140545419
Аккаунт 0 запущен
['dsfhjhasfjh']
Всего чатов 17450
/bot_dsfhjhasfjh
[[1002363042], [-1]]
/select_account
/bot_dsfhjhasfjh
[[1002363042], [0]]
/set_spam_message
/clear
Hi! How did I end up here?
['Hi! How did I end up here?']
Who am I? Where am I?
['Hi! How did I end up here?', 'Who am I? Where am I?']
What's going on here?
['Hi! How did I end up here?', 'Who am I? Where am I?', "What's going on here?"]
What kind of chat?
['Hi! How did I end up here?', 'Who am I? Where am I?', "What's going on here?", 'What kind of chat?']
/save
Save message
main.py:70: RuntimeWarning: coroutine 'resource_path' was never awaited
  with open(resource_path('message.ini'), 'w', encoding='utf-8') as fp:
RuntimeWarning: Enable tracemalloc to get the object allocation traceback
expected str, bytes or os.PathLike object, not coroutine
Traceback (most recent call last):
  File "/Users/pavel/Library/Python/3.8/lib/python/site-packages/pyrogram/dispatcher.py", line 222, in handler_worker
    await handler.callback(self.client, *args)
  File "main.py", line 326, in bot_handl
    await Save("Message")
  File "main.py", line 70, in Save
    with open(resource_path('message.ini'), 'w', encoding='utf-8') as fp:
TypeError: expected str, bytes or os.PathLike object, not coroutine
^[[A
^X^C%                                                                           pavel@iMac-Pavel spam-bot % 
pavel@iMac-Pavel spam-bot % python3 main.py
chats
В работе 1 аккаунтов
ID бота: 5140545419
Аккаунт 0 запущен
['dsfhjhasfjh']
Всего чатов 17450
/select_account
[[1002363042], [-1]]
/bot_dsfhjhasfjh
[[1002363042], [0]]
/help
/set_spam_message
Hi! How did I end up here?
["Hello, I am promoting telegram channels and adding traffic from other people's channels! If you are interested, write in PM", 'Hi, if you need traffic to your Telegram channel, write in private messages!', 'Hi! How did I end up here?']
Who am I? Where am I?
["Hello, I am promoting telegram channels and adding traffic from other people's channels! If you are interested, write in PM", 'Hi, if you need traffic to your Telegram channel, write in private messages!', 'Hi! How did I end up here?', 'Who am I? Where am I?']
What's going on here?
["Hello, I am promoting telegram channels and adding traffic from other people's channels! If you are interested, write in PM", 'Hi, if you need traffic to your Telegram channel, write in private messages!', 'Hi! How did I end up here?', 'Who am I? Where am I?', "What's going on here?"]
What kind of chat?
["Hello, I am promoting telegram channels and adding traffic from other people's channels! If you are interested, write in PM", 'Hi, if you need traffic to your Telegram channel, write in private messages!', 'Hi! How did I end up here?', 'Who am I? Where am I?', "What's going on here?", 'What kind of chat?']
/clear
Hi! How did I end up here?
['Hi! How did I end up here?']
Who am I? Where am I?
['Hi! How did I end up here?', 'Who am I? Where am I?']
What's going on here?
['Hi! How did I end up here?', 'Who am I? Where am I?', "What's going on here?"]
What kind of chat?
['Hi! How did I end up here?', 'Who am I? Where am I?', "What's going on here?", 'What kind of chat?']
/save
Save message
^C
^[[A%                                                                           pavel@iMac-Pavel spam-bot % 
pavel@iMac-Pavel spam-bot % python3 main.py
chats
В работе 1 аккаунтов
Traceback (most recent call last):
  File "main.py", line 464, in <module>
    asyncio.run(main())
  File "/Library/Developer/CommandLineTools/Library/Frameworks/Python3.framework/Versions/3.8/lib/python3.8/asyncio/runners.py", line 43, in run
    return loop.run_until_complete(main)
  File "/Library/Developer/CommandLineTools/Library/Frameworks/Python3.framework/Versions/3.8/lib/python3.8/asyncio/base_events.py", line 616, in run_until_complete
    return future.result()
  File "main.py", line 425, in main
    await open_from_file()
  File "main.py", line 48, in open_from_file
    data = fp.read_lines()  
AttributeError: '_io.TextIOWrapper' object has no attribute 'read_lines'
pavel@iMac-Pavel spam-bot % python3 main.py
chats
В работе 1 аккаунтов
Traceback (most recent call last):
  File "main.py", line 464, in <module>
    asyncio.run(main())
  File "/Library/Developer/CommandLineTools/Library/Frameworks/Python3.framework/Versions/3.8/lib/python3.8/asyncio/runners.py", line 43, in run
    return loop.run_until_complete(main)
  File "/Library/Developer/CommandLineTools/Library/Frameworks/Python3.framework/Versions/3.8/lib/python3.8/asyncio/base_events.py", line 616, in run_until_complete
    return future.result()
  File "main.py", line 425, in main
    await open_from_file()
  File "main.py", line 50, in open_from_file
    accounts_list[i].message_list = data.split('&')
AttributeError: 'list' object has no attribute 'split'
pavel@iMac-Pavel spam-bot % python3 main.py
chats
В работе 1 аккаунтов
['Hi! How did I end up here?', 'Who am I? Where am I?', "What's going on here?", 'What kind of chat?\n']
ID бота: 5140545419
Аккаунт 0 запущен
['dsfhjhasfjh']
Всего чатов 17450
^C
pavel@iMac-Pavel spam-bot % 
pavel@iMac-Pavel spam-bot % python3 main.py
chats
В работе 1 аккаунтов
['Hi! How did I end up here?', 'Who am I? Where am I?', "What's going on here?", 'What kind of chat?']
ID бота: 5140545419
Аккаунт 0 запущен
['dsfhjhasfjh']
Всего чатов 17450
^C
pavel@iMac-Pavel spam-bot % 
pavel@iMac-Pavel spam-bot % python3 main.py
chats
В работе 1 аккаунтов
ID бота: 5140545419
Аккаунт 0 запущен
['dsfhjhasfjh']
Всего чатов 17450
^C
pavel@iMac-Pavel spam-bot % 
pavel@iMac-Pavel spam-bot % python3 main.py
chats
В работе 1 аккаунтов
['Hi! How did I end up here?', 'Who am I? Where am I?', "What's going on here?", 'What kind of chat?']
ID бота: 5140545419
Аккаунт 0 запущен
['dsfhjhasfjh']
Всего чатов 17450
/status
[[1002363042], [-1]]
/select_account
/bot_dsfhjhasfjh
[[1002363042], [0]]
/status
^C
pavel@iMac-Pavel spam-bot % 
pavel@iMac-Pavel spam-bot % python3 main.py
chats
В работе 1 аккаунтов
['Hi! How did I end up here?', 'Who am I? Where am I?', "What's going on here?", 'What kind of chat?']
ID бота: 5140545419
Аккаунт 0 запущен
['dsfhjhasfjh']
Всего чатов 17450
/status
[[1002363042], [-1]]
/select_account
/bot_dsfhjhasfjh
[[1002363042], [0]]
/help
/status
/start_spam
'Message' object has no attribute 'repy'
Traceback (most recent call last):
  File "/Users/pavel/Library/Python/3.8/lib/python/site-packages/pyrogram/dispatcher.py", line 222, in handler_worker
    await handler.callback(self.client, *args)
  File "main.py", line 382, in bot_handl
    await spamming(n, message)
  File "main.py", line 95, in spamming
    await message.repy('Спам запущен')
AttributeError: 'Message' object has no attribute 'repy'
^C
^[[A%                                                                           pavel@iMac-Pavel spam-bot % 
pavel@iMac-Pavel spam-bot % python3 main.py
chats
В работе 1 аккаунтов
['Hi! How did I end up here?', 'Who am I? Where am I?', "What's going on here?", 'What kind of chat?']
ID бота: 5140545419
Аккаунт 0 запущен
['dsfhjhasfjh']
Всего чатов 17450
/status
[[1002363042], [-1]]
/select_account
/bot_dsfhjhasfjh
[[1002363042], [0]]
/status
/start_spam
chatterboxenglish
koistarterofficial
Telegram says: [403 CHAT_WRITE_FORBIDDEN] - You don't have rights to send messages in this chat (caused by "messages.SendMessage")
cryptoclashglobal
plutoniansgame
galaxywinofficial11
Telegram says: [403 CHAT_WRITE_FORBIDDEN] - You don't have rights to send messages in this chat (caused by "messages.SendMessage")
theblockcircle
Telegram says: [400 USER_NOT_PARTICIPANT] - The user is not a member of this chat (caused by "channels.LeaveChannel")
/status
indgirlschattinggroup
Telegram says: [400 USERNAME_NOT_OCCUPIED] - The username is not occupied by anyone (caused by "contacts.ResolveUsername")
deuxpadofc
telexmovies
moonforcetoken
bitkeep
Telegram says: [400 USER_NOT_PARTICIPANT] - The user is not a member of this chat (caused by "channels.LeaveChannel")
/status
strongblock_io
Telegram says: [400 USER_NOT_PARTICIPANT] - The user is not a member of this chat (caused by "channels.LeaveChannel")
polygonofficial
'Username not found: strongblock_io'
wallsteetbets13
Telegram says: [400 USERNAME_NOT_OCCUPIED] - The username is not occupied by anyone (caused by "contacts.ResolveUsername")
mobox_io
Telegram says: [400 USER_NOT_PARTICIPANT] - The user is not a member of this chat (caused by "channels.LeaveChannel")
risedefendersvietnamese
oasisswap_org
globalcryptoworld
Telegram says: [403 CHAT_WRITE_FORBIDDEN] - You don't have rights to send messages in this chat (caused by "messages.SendMessage")
thecryptostalkers
international_english_russian
/status
lom_official
/status
hindi_chatting_grp
/status
None
Telegram says: [400 CHAT_ADMIN_REQUIRED] - The method requires chat admin privileges (caused by "messages.SendMessage")
international_chatting_legends
Telegram says: [400 CHAT_ADMIN_REQUIRED] - The method requires chat admin privileges (caused by "messages.SendMessage")
multipad_official
english_chatting_cafe
redminote10prodiscussion
ebgame_global
binanceindian
cryptowarrior24
otakuzdream
the_4_cryptoeagles
/help
Telegram says: [403 CHAT_WRITE_FORBIDDEN] - You don't have rights to send messages in this chat (caused by "messages.SendMessage")
cryptobantergroup
cryptopandaglobal
xiaomiuietagroup
Telegram says: [403 CHAT_WRITE_FORBIDDEN] - You don't have rights to send messages in this chat (caused by "messages.SendMessage")
bscstation
Unable to connect due to network issues: timed out
Telegram says: [400 USER_NOT_PARTICIPANT] - The user is not a member of this chat (caused by "channels.LeaveChannel")
ultiarena
polkawarchat
Unable to connect due to network issues: timed out
Unable to connect due to network issues: timed out
Telegram says: [400 USER_NOT_PARTICIPANT] - The user is not a member of this chat (caused by "channels.LeaveChannel")
cryptoislandgroup
Telegram says: [403 CHAT_WRITE_FORBIDDEN] - You don't have rights to send messages in this chat (caused by "messages.SendMessage")
hotcross
Telegram says: [403 CHAT_WRITE_FORBIDDEN] - You don't have rights to send messages in this chat (caused by "messages.SendMessage")
airdropsupportgroup2
Unable to connect due to network issues: timed out
Unable to connect due to network issues: timed out
nagakingdom
socket.send() raised exception.
socket.send() raised exception.
socket.send() raised exception.
socket.send() raised exception.
socket.send() raised exception.
socket.send() raised exception.
socket.send() raised exception.
socket.send() raised exception.
socket.send() raised exception.
socket.send() raised exception.
socket.send() raised exception.
socket.send() raised exception.
socket.send() raised exception.
socket.send() raised exception.
socket.send() raised exception.
socket.send() raised exception.
socket.send() raised exception.
socket.send() raised exception.
socket.send() raised exception.
socket.send() raised exception.
socket.send() raised exception.
socket.send() raised exception.
socket.send() raised exception.
socket.send() raised exception.
socket.send() raised exception.
socket.send() raised exception.
socket.send() raised exception.
socket.send() raised exception.
socket.send() raised exception.
socket.send() raised exception.
socket.send() raised exception.
socket.send() raised exception.
socket.send() raised exception.
socket.send() raised exception.
socket.send() raised exception.
socket.send() raised exception.
socket.send() raised exception.
socket.send() raised exception.
socket.send() raised exception.
socket.send() raised exception.
socket.send() raised exception.
socket.send() raised exception.
socket.send() raised exception.
socket.send() raised exception.
socket.send() raised exception.
socket.send() raised exception.
socket.send() raised exception.
socket.send() raised exception.
socket.send() raised exception.
socket.send() raised exception.
socket.send() raised exception.
socket.send() raised exception.
socket.send() raised exception.
socket.send() raised exception.
socket.send() raised exception.
socket.send() raised exception.
socket.send() raised exception.
socket.send() raised exception.
socket.send() raised exception.
socket.send() raised exception.
socket.send() raised exception.
socket.send() raised exception.
socket.send() raised exception.
socket.send() raised exception.
socket.send() raised exception.
socket.send() raised exception.
socket.send() raised exception.
socket.send() raised exception.
socket.send() raised exception.
socket.send() raised exception.
socket.send() raised exception.
socket.send() raised exception.
socket.send() raised exception.
socket.send() raised exception.
socket.send() raised exception.
socket.send() raised exception.
socket.send() raised exception.
socket.send() raised exception.
socket.send() raised exception.
socket.send() raised exception.
socket.send() raised exception.
socket.send() raised exception.
socket.send() raised exception.
socket.send() raised exception.
socket.send() raised exception.
socket.send() raised exception.
socket.send() raised exception.
socket.send() raised exception.
socket.send() raised exception.
socket.send() raised exception.
socket.send() raised exception.
socket.send() raised exception.
socket.send() raised exception.
socket.send() raised exception.
[5] Retrying "updates.GetChannelDifference" due to Connection lost
socket.send() raised exception.
[5] Retrying "updates.GetChannelDifference" due to Connection lost
socket.send() raised exception.
[5] Retrying "updates.GetChannelDifference" due to Connection lost
socket.send() raised exception.
[5] Retrying "updates.GetChannelDifference" due to Connection lost
socket.send() raised exception.
[5] Retrying "updates.GetChannelDifference" due to Connection lost
socket.send() raised exception.
socket.send() raised exception.
socket.send() raised exception.
socket.send() raised exception.
socket.send() raised exception.
socket.send() raised exception.
socket.send() raised exception.
socket.send() raised exception.
socket.send() raised exception.
socket.send() raised exception.
socket.send() raised exception.
socket.send() raised exception.
socket.send() raised exception.
socket.send() raised exception.
socket.send() raised exception.
socket.send() raised exception.
socket.send() raised exception.
socket.send() raised exception.
socket.send() raised exception.
socket.send() raised exception.
Task exception was never retrieved
future: <Task finished name='Task-54533' coro=<Client.handle_updates() done, defined at /Users/pavel/Library/Python/3.8/lib/python/site-packages/pyrogram/client.py:525> exception=TimeoutError()>
Traceback (most recent call last):
  File "/Users/pavel/Library/Python/3.8/lib/python/site-packages/pyrogram/client.py", line 552, in handle_updates
    diff = await self.send(
  File "/Users/pavel/Library/Python/3.8/lib/python/site-packages/pyrogram/methods/advanced/send.py", line 77, in send
    r = await self.session.send(
  File "/Users/pavel/Library/Python/3.8/lib/python/site-packages/pyrogram/session/session.py", line 382, in send
    return await self.send(data, retries - 1, timeout)
  File "/Users/pavel/Library/Python/3.8/lib/python/site-packages/pyrogram/session/session.py", line 382, in send
    return await self.send(data, retries - 1, timeout)
  File "/Users/pavel/Library/Python/3.8/lib/python/site-packages/pyrogram/session/session.py", line 382, in send
    return await self.send(data, retries - 1, timeout)
  [Previous line repeated 2 more times]
  File "/Users/pavel/Library/Python/3.8/lib/python/site-packages/pyrogram/session/session.py", line 375, in send
    raise e from None
  File "/Users/pavel/Library/Python/3.8/lib/python/site-packages/pyrogram/session/session.py", line 362, in send
    return await self._send(data, timeout=timeout)
  File "/Users/pavel/Library/Python/3.8/lib/python/site-packages/pyrogram/session/session.py", line 327, in _send
    raise TimeoutError
TimeoutError
Task exception was never retrieved
future: <Task finished name='Task-54544' coro=<Client.handle_updates() done, defined at /Users/pavel/Library/Python/3.8/lib/python/site-packages/pyrogram/client.py:525> exception=TimeoutError()>
Traceback (most recent call last):
  File "/Users/pavel/Library/Python/3.8/lib/python/site-packages/pyrogram/client.py", line 552, in handle_updates
    diff = await self.send(
  File "/Users/pavel/Library/Python/3.8/lib/python/site-packages/pyrogram/methods/advanced/send.py", line 77, in send
    r = await self.session.send(
  File "/Users/pavel/Library/Python/3.8/lib/python/site-packages/pyrogram/session/session.py", line 382, in send
    return await self.send(data, retries - 1, timeout)
  File "/Users/pavel/Library/Python/3.8/lib/python/site-packages/pyrogram/session/session.py", line 382, in send
    return await self.send(data, retries - 1, timeout)
  File "/Users/pavel/Library/Python/3.8/lib/python/site-packages/pyrogram/session/session.py", line 382, in send
    return await self.send(data, retries - 1, timeout)
  [Previous line repeated 2 more times]
  File "/Users/pavel/Library/Python/3.8/lib/python/site-packages/pyrogram/session/session.py", line 375, in send
    raise e from None
  File "/Users/pavel/Library/Python/3.8/lib/python/site-packages/pyrogram/session/session.py", line 362, in send
    return await self._send(data, timeout=timeout)
  File "/Users/pavel/Library/Python/3.8/lib/python/site-packages/pyrogram/session/session.py", line 327, in _send
    raise TimeoutError
TimeoutError
Task exception was never retrieved
future: <Task finished name='Task-54550' coro=<Client.handle_updates() done, defined at /Users/pavel/Library/Python/3.8/lib/python/site-packages/pyrogram/client.py:525> exception=TimeoutError()>
Traceback (most recent call last):
  File "/Users/pavel/Library/Python/3.8/lib/python/site-packages/pyrogram/client.py", line 552, in handle_updates
    diff = await self.send(
  File "/Users/pavel/Library/Python/3.8/lib/python/site-packages/pyrogram/methods/advanced/send.py", line 77, in send
    r = await self.session.send(
  File "/Users/pavel/Library/Python/3.8/lib/python/site-packages/pyrogram/session/session.py", line 382, in send
    return await self.send(data, retries - 1, timeout)
  File "/Users/pavel/Library/Python/3.8/lib/python/site-packages/pyrogram/session/session.py", line 382, in send
    return await self.send(data, retries - 1, timeout)
  File "/Users/pavel/Library/Python/3.8/lib/python/site-packages/pyrogram/session/session.py", line 382, in send
    return await self.send(data, retries - 1, timeout)
  [Previous line repeated 2 more times]
  File "/Users/pavel/Library/Python/3.8/lib/python/site-packages/pyrogram/session/session.py", line 375, in send
    raise e from None
  File "/Users/pavel/Library/Python/3.8/lib/python/site-packages/pyrogram/session/session.py", line 362, in send
    return await self._send(data, timeout=timeout)
  File "/Users/pavel/Library/Python/3.8/lib/python/site-packages/pyrogram/session/session.py", line 327, in _send
    raise TimeoutError
TimeoutError
Task exception was never retrieved
future: <Task finished name='Task-54558' coro=<Client.handle_updates() done, defined at /Users/pavel/Library/Python/3.8/lib/python/site-packages/pyrogram/client.py:525> exception=TimeoutError()>
Traceback (most recent call last):
  File "/Users/pavel/Library/Python/3.8/lib/python/site-packages/pyrogram/client.py", line 552, in handle_updates
    diff = await self.send(
  File "/Users/pavel/Library/Python/3.8/lib/python/site-packages/pyrogram/methods/advanced/send.py", line 77, in send
    r = await self.session.send(
  File "/Users/pavel/Library/Python/3.8/lib/python/site-packages/pyrogram/session/session.py", line 382, in send
    return await self.send(data, retries - 1, timeout)
  File "/Users/pavel/Library/Python/3.8/lib/python/site-packages/pyrogram/session/session.py", line 382, in send
    return await self.send(data, retries - 1, timeout)
  File "/Users/pavel/Library/Python/3.8/lib/python/site-packages/pyrogram/session/session.py", line 382, in send
    return await self.send(data, retries - 1, timeout)
  [Previous line repeated 2 more times]
  File "/Users/pavel/Library/Python/3.8/lib/python/site-packages/pyrogram/session/session.py", line 375, in send
    raise e from None
  File "/Users/pavel/Library/Python/3.8/lib/python/site-packages/pyrogram/session/session.py", line 362, in send
    return await self._send(data, timeout=timeout)
  File "/Users/pavel/Library/Python/3.8/lib/python/site-packages/pyrogram/session/session.py", line 327, in _send
    raise TimeoutError
TimeoutError
Task exception was never retrieved
future: <Task finished name='Task-54564' coro=<Client.handle_updates() done, defined at /Users/pavel/Library/Python/3.8/lib/python/site-packages/pyrogram/client.py:525> exception=TimeoutError()>
Traceback (most recent call last):
  File "/Users/pavel/Library/Python/3.8/lib/python/site-packages/pyrogram/client.py", line 552, in handle_updates
    diff = await self.send(
  File "/Users/pavel/Library/Python/3.8/lib/python/site-packages/pyrogram/methods/advanced/send.py", line 77, in send
    r = await self.session.send(
  File "/Users/pavel/Library/Python/3.8/lib/python/site-packages/pyrogram/session/session.py", line 382, in send
    return await self.send(data, retries - 1, timeout)
  File "/Users/pavel/Library/Python/3.8/lib/python/site-packages/pyrogram/session/session.py", line 382, in send
    return await self.send(data, retries - 1, timeout)
  File "/Users/pavel/Library/Python/3.8/lib/python/site-packages/pyrogram/session/session.py", line 382, in send
    return await self.send(data, retries - 1, timeout)
  [Previous line repeated 2 more times]
  File "/Users/pavel/Library/Python/3.8/lib/python/site-packages/pyrogram/session/session.py", line 375, in send
    raise e from None
  File "/Users/pavel/Library/Python/3.8/lib/python/site-packages/pyrogram/session/session.py", line 362, in send
    return await self._send(data, timeout=timeout)
  File "/Users/pavel/Library/Python/3.8/lib/python/site-packages/pyrogram/session/session.py", line 327, in _send
    raise TimeoutError
TimeoutError
[5] Retrying "contacts.ResolveUsername" due to TimeoutError()
socket.send() raised exception.
socket.send() raised exception.
socket.send() raised exception.
[5] Retrying "updates.GetChannelDifference" due to TimeoutError()
[5] Retrying "updates.GetChannelDifference" due to TimeoutError()
[5] Retrying "updates.GetChannelDifference" due to TimeoutError()
[5] Retrying "updates.GetChannelDifference" due to TimeoutError()
[5] Retrying "updates.GetChannelDifference" due to TimeoutError()
[5] Retrying "updates.GetChannelDifference" due to TimeoutError()
[5] Retrying "updates.GetChannelDifference" due to TimeoutError()
[5] Retrying "updates.GetChannelDifference" due to TimeoutError()
[5] Retrying "updates.GetChannelDifference" due to TimeoutError()
[5] Retrying "updates.GetChannelDifference" due to TimeoutError()
[5] Retrying "updates.GetChannelDifference" due to TimeoutError()
socket.send() raised exception.
socket.send() raised exception.
socket.send() raised exception.
socket.send() raised exception.
socket.send() raised exception.
socket.send() raised exception.
socket.send() raised exception.
socket.send() raised exception.
socket.send() raised exception.
socket.send() raised exception.
socket.send() raised exception.
[5] Retrying "updates.GetChannelDifference" due to TimeoutError()
[5] Retrying "updates.GetChannelDifference" due to TimeoutError()

Task exception was never retrieved
future: <Task finished name='Task-54594' coro=<Client.handle_updates() done, defined at /Users/pavel/Library/Python/3.8/lib/python/site-packages/pyrogram/client.py:525> exception=TimeoutError()>
Traceback (most recent call last):
  File "/Users/pavel/Library/Python/3.8/lib/python/site-packages/pyrogram/client.py", line 552, in handle_updates
    diff = await self.send(
  File "/Users/pavel/Library/Python/3.8/lib/python/site-packages/pyrogram/methods/advanced/send.py", line 77, in send
    r = await self.session.send(
  File "/Users/pavel/Library/Python/3.8/lib/python/site-packages/pyrogram/session/session.py", line 382, in send
    return await self.send(data, retries - 1, timeout)
  File "/Users/pavel/Library/Python/3.8/lib/python/site-packages/pyrogram/session/session.py", line 382, in send
    return await self.send(data, retries - 1, timeout)
  File "/Users/pavel/Library/Python/3.8/lib/python/site-packages/pyrogram/session/session.py", line 382, in send
    return await self.send(data, retries - 1, timeout)
  [Previous line repeated 2 more times]
  File "/Users/pavel/Library/Python/3.8/lib/python/site-packages/pyrogram/session/session.py", line 375, in send
    raise e from None
  File "/Users/pavel/Library/Python/3.8/lib/python/site-packages/pyrogram/session/session.py", line 362, in send
    return await self._send(data, timeout=timeout)
  File "/Users/pavel/Library/Python/3.8/lib/python/site-packages/pyrogram/session/session.py", line 327, in _send
    raise TimeoutError
TimeoutError
Task exception was never retrieved
future: <Task finished name='Task-54600' coro=<Client.handle_updates() done, defined at /Users/pavel/Library/Python/3.8/lib/python/site-packages/pyrogram/client.py:525> exception=TimeoutError()>
Traceback (most recent call last):
  File "/Users/pavel/Library/Python/3.8/lib/python/site-packages/pyrogram/client.py", line 552, in handle_updates
    diff = await self.send(
  File "/Users/pavel/Library/Python/3.8/lib/python/site-packages/pyrogram/methods/advanced/send.py", line 77, in send
    r = await self.session.send(
  File "/Users/pavel/Library/Python/3.8/lib/python/site-packages/pyrogram/session/session.py", line 382, in send
    return await self.send(data, retries - 1, timeout)
  File "/Users/pavel/Library/Python/3.8/lib/python/site-packages/pyrogram/session/session.py", line 382, in send
    return await self.send(data, retries - 1, timeout)
  File "/Users/pavel/Library/Python/3.8/lib/python/site-packages/pyrogram/session/session.py", line 382, in send
    return await self.send(data, retries - 1, timeout)
  [Previous line repeated 2 more times]
  File "/Users/pavel/Library/Python/3.8/lib/python/site-packages/pyrogram/session/session.py", line 375, in send
    raise e from None
  File "/Users/pavel/Library/Python/3.8/lib/python/site-packages/pyrogram/session/session.py", line 362, in send
    return await self._send(data, timeout=timeout)
  File "/Users/pavel/Library/Python/3.8/lib/python/site-packages/pyrogram/session/session.py", line 327, in _send
    raise TimeoutError
TimeoutError
Task exception was never retrieved
future: <Task finished name='Task-54601' coro=<Client.handle_updates() done, defined at /Users/pavel/Library/Python/3.8/lib/python/site-packages/pyrogram/client.py:525> exception=TimeoutError()>
Traceback (most recent call last):
  File "/Users/pavel/Library/Python/3.8/lib/python/site-packages/pyrogram/client.py", line 552, in handle_updates
    diff = await self.send(
  File "/Users/pavel/Library/Python/3.8/lib/python/site-packages/pyrogram/methods/advanced/send.py", line 77, in send
    r = await self.session.send(
  File "/Users/pavel/Library/Python/3.8/lib/python/site-packages/pyrogram/session/session.py", line 382, in send
    return await self.send(data, retries - 1, timeout)
  File "/Users/pavel/Library/Python/3.8/lib/python/site-packages/pyrogram/session/session.py", line 382, in send
    return await self.send(data, retries - 1, timeout)
  File "/Users/pavel/Library/Python/3.8/lib/python/site-packages/pyrogram/session/session.py", line 382, in send
    return await self.send(data, retries - 1, timeout)
  [Previous line repeated 2 more times]
  File "/Users/pavel/Library/Python/3.8/lib/python/site-packages/pyrogram/session/session.py", line 375, in send
    raise e from None
  File "/Users/pavel/Library/Python/3.8/lib/python/site-packages/pyrogram/session/session.py", line 362, in send
    return await self._send(data, timeout=timeout)
  File "/Users/pavel/Library/Python/3.8/lib/python/site-packages/pyrogram/session/session.py", line 327, in _send
    raise TimeoutError
TimeoutError
Task exception was never retrieved
future: <Task finished name='Task-54607' coro=<Client.handle_updates() done, defined at /Users/pavel/Library/Python/3.8/lib/python/site-packages/pyrogram/client.py:525> exception=TimeoutError()>
Traceback (most recent call last):
  File "/Users/pavel/Library/Python/3.8/lib/python/site-packages/pyrogram/client.py", line 552, in handle_updates
    diff = await self.send(
  File "/Users/pavel/Library/Python/3.8/lib/python/site-packages/pyrogram/methods/advanced/send.py", line 77, in send
    r = await self.session.send(
  File "/Users/pavel/Library/Python/3.8/lib/python/site-packages/pyrogram/session/session.py", line 382, in send
    return await self.send(data, retries - 1, timeout)
  File "/Users/pavel/Library/Python/3.8/lib/python/site-packages/pyrogram/session/session.py", line 382, in send
    return await self.send(data, retries - 1, timeout)
  File "/Users/pavel/Library/Python/3.8/lib/python/site-packages/pyrogram/session/session.py", line 382, in send
    return await self.send(data, retries - 1, timeout)
  [Previous line repeated 2 more times]
  File "/Users/pavel/Library/Python/3.8/lib/python/site-packages/pyrogram/session/session.py", line 375, in send
    raise e from None
  File "/Users/pavel/Library/Python/3.8/lib/python/site-packages/pyrogram/session/session.py", line 362, in send
    return await self._send(data, timeout=timeout)
  File "/Users/pavel/Library/Python/3.8/lib/python/site-packages/pyrogram/session/session.py", line 327, in _send
    raise TimeoutError
TimeoutError
[5] Retrying "updates.GetChannelDifference" due to TimeoutError()
[5] Retrying "updates.GetChannelDifference" due to TimeoutError()
[5] Retrying "updates.GetChannelDifference" due to TimeoutError()
Task exception was never retrieved
future: <Task finished name='Task-54669' coro=<Client.handle_updates() done, defined at /Users/pavel/Library/Python/3.8/lib/python/site-packages/pyrogram/client.py:525> exception=TimeoutError()>
Traceback (most recent call last):
  File "/Users/pavel/Library/Python/3.8/lib/python/site-packages/pyrogram/client.py", line 552, in handle_updates
    diff = await self.send(
  File "/Users/pavel/Library/Python/3.8/lib/python/site-packages/pyrogram/methods/advanced/send.py", line 77, in send
    r = await self.session.send(
  File "/Users/pavel/Library/Python/3.8/lib/python/site-packages/pyrogram/session/session.py", line 382, in send
    return await self.send(data, retries - 1, timeout)
  File "/Users/pavel/Library/Python/3.8/lib/python/site-packages/pyrogram/session/session.py", line 382, in send
    return await self.send(data, retries - 1, timeout)
  File "/Users/pavel/Library/Python/3.8/lib/python/site-packages/pyrogram/session/session.py", line 382, in send
    return await self.send(data, retries - 1, timeout)
  [Previous line repeated 2 more times]
  File "/Users/pavel/Library/Python/3.8/lib/python/site-packages/pyrogram/session/session.py", line 375, in send
    raise e from None
  File "/Users/pavel/Library/Python/3.8/lib/python/site-packages/pyrogram/session/session.py", line 362, in send
    return await self._send(data, timeout=timeout)
  File "/Users/pavel/Library/Python/3.8/lib/python/site-packages/pyrogram/session/session.py", line 327, in _send
    raise TimeoutError
TimeoutError
Task exception was never retrieved
future: <Task finished name='Task-54674' coro=<Client.handle_updates() done, defined at /Users/pavel/Library/Python/3.8/lib/python/site-packages/pyrogram/client.py:525> exception=TimeoutError()>
Traceback (most recent call last):
  File "/Users/pavel/Library/Python/3.8/lib/python/site-packages/pyrogram/client.py", line 552, in handle_updates
    diff = await self.send(
  File "/Users/pavel/Library/Python/3.8/lib/python/site-packages/pyrogram/methods/advanced/send.py", line 77, in send
    r = await self.session.send(
  File "/Users/pavel/Library/Python/3.8/lib/python/site-packages/pyrogram/session/session.py", line 382, in send
    return await self.send(data, retries - 1, timeout)
  File "/Users/pavel/Library/Python/3.8/lib/python/site-packages/pyrogram/session/session.py", line 382, in send
    return await self.send(data, retries - 1, timeout)
  File "/Users/pavel/Library/Python/3.8/lib/python/site-packages/pyrogram/session/session.py", line 382, in send
    return await self.send(data, retries - 1, timeout)
  [Previous line repeated 2 more times]
  File "/Users/pavel/Library/Python/3.8/lib/python/site-packages/pyrogram/session/session.py", line 375, in send
    raise e from None
  File "/Users/pavel/Library/Python/3.8/lib/python/site-packages/pyrogram/session/session.py", line 362, in send
    return await self._send(data, timeout=timeout)
  File "/Users/pavel/Library/Python/3.8/lib/python/site-packages/pyrogram/session/session.py", line 327, in _send
    raise TimeoutError
TimeoutError
Task exception was never retrieved
future: <Task finished name='Task-54685' coro=<Client.handle_updates() done, defined at /Users/pavel/Library/Python/3.8/lib/python/site-packages/pyrogram/client.py:525> exception=TimeoutError()>
Traceback (most recent call last):
  File "/Users/pavel/Library/Python/3.8/lib/python/site-packages/pyrogram/client.py", line 552, in handle_updates
    diff = await self.send(
  File "/Users/pavel/Library/Python/3.8/lib/python/site-packages/pyrogram/methods/advanced/send.py", line 77, in send
    r = await self.session.send(
  File "/Users/pavel/Library/Python/3.8/lib/python/site-packages/pyrogram/session/session.py", line 382, in send
    return await self.send(data, retries - 1, timeout)
  File "/Users/pavel/Library/Python/3.8/lib/python/site-packages/pyrogram/session/session.py", line 382, in send
    return await self.send(data, retries - 1, timeout)
  File "/Users/pavel/Library/Python/3.8/lib/python/site-packages/pyrogram/session/session.py", line 382, in send
    return await self.send(data, retries - 1, timeout)
  [Previous line repeated 2 more times]
  File "/Users/pavel/Library/Python/3.8/lib/python/site-packages/pyrogram/session/session.py", line 375, in send
    raise e from None
  File "/Users/pavel/Library/Python/3.8/lib/python/site-packages/pyrogram/session/session.py", line 362, in send
    return await self._send(data, timeout=timeout)
  File "/Users/pavel/Library/Python/3.8/lib/python/site-packages/pyrogram/session/session.py", line 327, in _send
    raise TimeoutError
TimeoutError
Task exception was never retrieved
future: <Task finished name='Task-54690' coro=<Client.handle_updates() done, defined at /Users/pavel/Library/Python/3.8/lib/python/site-packages/pyrogram/client.py:525> exception=TimeoutError()>
Traceback (most recent call last):
  File "/Users/pavel/Library/Python/3.8/lib/python/site-packages/pyrogram/client.py", line 552, in handle_updates
    diff = await self.send(
  File "/Users/pavel/Library/Python/3.8/lib/python/site-packages/pyrogram/methods/advanced/send.py", line 77, in send
    r = await self.session.send(
  File "/Users/pavel/Library/Python/3.8/lib/python/site-packages/pyrogram/session/session.py", line 382, in send
    return await self.send(data, retries - 1, timeout)
  File "/Users/pavel/Library/Python/3.8/lib/python/site-packages/pyrogram/session/session.py", line 382, in send
    return await self.send(data, retries - 1, timeout)
  File "/Users/pavel/Library/Python/3.8/lib/python/site-packages/pyrogram/session/session.py", line 382, in send
    return await self.send(data, retries - 1, timeout)
  [Previous line repeated 2 more times]
  File "/Users/pavel/Library/Python/3.8/lib/python/site-packages/pyrogram/session/session.py", line 375, in send
    raise e from None
  File "/Users/pavel/Library/Python/3.8/lib/python/site-packages/pyrogram/session/session.py", line 362, in send
    return await self._send(data, timeout=timeout)
  File "/Users/pavel/Library/Python/3.8/lib/python/site-packages/pyrogram/session/session.py", line 327, in _send
    raise TimeoutError
TimeoutError
Task exception was never retrieved
future: <Task finished name='Task-54696' coro=<Client.handle_updates() done, defined at /Users/pavel/Library/Python/3.8/lib/python/site-packages/pyrogram/client.py:525> exception=TimeoutError()>
Traceback (most recent call last):
  File "/Users/pavel/Library/Python/3.8/lib/python/site-packages/pyrogram/client.py", line 552, in handle_updates
    diff = await self.send(
  File "/Users/pavel/Library/Python/3.8/lib/python/site-packages/pyrogram/methods/advanced/send.py", line 77, in send
    r = await self.session.send(
  File "/Users/pavel/Library/Python/3.8/lib/python/site-packages/pyrogram/session/session.py", line 382, in send
    return await self.send(data, retries - 1, timeout)
  File "/Users/pavel/Library/Python/3.8/lib/python/site-packages/pyrogram/session/session.py", line 382, in send
    return await self.send(data, retries - 1, timeout)
  File "/Users/pavel/Library/Python/3.8/lib/python/site-packages/pyrogram/session/session.py", line 382, in send
    return await self.send(data, retries - 1, timeout)
  [Previous line repeated 2 more times]
  File "/Users/pavel/Library/Python/3.8/lib/python/site-packages/pyrogram/session/session.py", line 375, in send
    raise e from None
  File "/Users/pavel/Library/Python/3.8/lib/python/site-packages/pyrogram/session/session.py", line 362, in send
    return await self._send(data, timeout=timeout)
  File "/Users/pavel/Library/Python/3.8/lib/python/site-packages/pyrogram/session/session.py", line 327, in _send
    raise TimeoutError
TimeoutError
Task exception was never retrieved
future: <Task finished name='Task-54702' coro=<Client.handle_updates() done, defined at /Users/pavel/Library/Python/3.8/lib/python/site-packages/pyrogram/client.py:525> exception=TimeoutError()>
Traceback (most recent call last):
  File "/Users/pavel/Library/Python/3.8/lib/python/site-packages/pyrogram/client.py", line 552, in handle_updates
    diff = await self.send(
  File "/Users/pavel/Library/Python/3.8/lib/python/site-packages/pyrogram/methods/advanced/send.py", line 77, in send
    r = await self.session.send(
  File "/Users/pavel/Library/Python/3.8/lib/python/site-packages/pyrogram/session/session.py", line 382, in send
    return await self.send(data, retries - 1, timeout)
  File "/Users/pavel/Library/Python/3.8/lib/python/site-packages/pyrogram/session/session.py", line 382, in send
    return await self.send(data, retries - 1, timeout)
  File "/Users/pavel/Library/Python/3.8/lib/python/site-packages/pyrogram/session/session.py", line 382, in send
    return await self.send(data, retries - 1, timeout)
  [Previous line repeated 2 more times]
  File "/Users/pavel/Library/Python/3.8/lib/python/site-packages/pyrogram/session/session.py", line 375, in send
    raise e from None
  File "/Users/pavel/Library/Python/3.8/lib/python/site-packages/pyrogram/session/session.py", line 362, in send
    return await self._send(data, timeout=timeout)
  File "/Users/pavel/Library/Python/3.8/lib/python/site-packages/pyrogram/session/session.py", line 327, in _send
    raise TimeoutError
TimeoutError
Task exception was never retrieved
future: <Task finished name='Task-54703' coro=<Client.handle_updates() done, defined at /Users/pavel/Library/Python/3.8/lib/python/site-packages/pyrogram/client.py:525> exception=TimeoutError()>
Traceback (most recent call last):
  File "/Users/pavel/Library/Python/3.8/lib/python/site-packages/pyrogram/client.py", line 552, in handle_updates
    diff = await self.send(
  File "/Users/pavel/Library/Python/3.8/lib/python/site-packages/pyrogram/methods/advanced/send.py", line 77, in send
    r = await self.session.send(
  File "/Users/pavel/Library/Python/3.8/lib/python/site-packages/pyrogram/session/session.py", line 382, in send
    return await self.send(data, retries - 1, timeout)
  File "/Users/pavel/Library/Python/3.8/lib/python/site-packages/pyrogram/session/session.py", line 382, in send
    return await self.send(data, retries - 1, timeout)
  File "/Users/pavel/Library/Python/3.8/lib/python/site-packages/pyrogram/session/session.py", line 382, in send
    return await self.send(data, retries - 1, timeout)
  [Previous line repeated 2 more times]
  File "/Users/pavel/Library/Python/3.8/lib/python/site-packages/pyrogram/session/session.py", line 375, in send
    raise e from None
  File "/Users/pavel/Library/Python/3.8/lib/python/site-packages/pyrogram/session/session.py", line 362, in send
    return await self._send(data, timeout=timeout)
  File "/Users/pavel/Library/Python/3.8/lib/python/site-packages/pyrogram/session/session.py", line 327, in _send
    raise TimeoutError
TimeoutError
socket.send() raised exception.
socket.send() raised exception.
socket.send() raised exception.
socket.send() raised exception.
socket.send() raised exception.
socket.send() raised exception.
socket.send() raised exception.
socket.send() raised exception.
socket.send() raised exception.
Task exception was never retrieved
future: <Task finished name='Task-54958' coro=<Client.handle_updates() done, defined at /Users/pavel/Library/Python/3.8/lib/python/site-packages/pyrogram/client.py:525> exception=TimeoutError()>
Traceback (most recent call last):
  File "/Users/pavel/Library/Python/3.8/lib/python/site-packages/pyrogram/client.py", line 552, in handle_updates
    diff = await self.send(
  File "/Users/pavel/Library/Python/3.8/lib/python/site-packages/pyrogram/methods/advanced/send.py", line 77, in send
    r = await self.session.send(
  File "/Users/pavel/Library/Python/3.8/lib/python/site-packages/pyrogram/session/session.py", line 382, in send
    return await self.send(data, retries - 1, timeout)
  File "/Users/pavel/Library/Python/3.8/lib/python/site-packages/pyrogram/session/session.py", line 382, in send
    return await self.send(data, retries - 1, timeout)
  File "/Users/pavel/Library/Python/3.8/lib/python/site-packages/pyrogram/session/session.py", line 382, in send
    return await self.send(data, retries - 1, timeout)
  [Previous line repeated 2 more times]
  File "/Users/pavel/Library/Python/3.8/lib/python/site-packages/pyrogram/session/session.py", line 375, in send
    raise e from None
  File "/Users/pavel/Library/Python/3.8/lib/python/site-packages/pyrogram/session/session.py", line 362, in send
    return await self._send(data, timeout=timeout)
  File "/Users/pavel/Library/Python/3.8/lib/python/site-packages/pyrogram/session/session.py", line 327, in _send
    raise TimeoutError
TimeoutError
Task exception was never retrieved
future: <Task finished name='Task-54959' coro=<Client.handle_updates() done, defined at /Users/pavel/Library/Python/3.8/lib/python/site-packages/pyrogram/client.py:525> exception=TimeoutError()>
Traceback (most recent call last):
  File "/Users/pavel/Library/Python/3.8/lib/python/site-packages/pyrogram/client.py", line 552, in handle_updates
    diff = await self.send(
  File "/Users/pavel/Library/Python/3.8/lib/python/site-packages/pyrogram/methods/advanced/send.py", line 77, in send
    r = await self.session.send(
  File "/Users/pavel/Library/Python/3.8/lib/python/site-packages/pyrogram/session/session.py", line 382, in send
    return await self.send(data, retries - 1, timeout)
  File "/Users/pavel/Library/Python/3.8/lib/python/site-packages/pyrogram/session/session.py", line 382, in send
    return await self.send(data, retries - 1, timeout)
  File "/Users/pavel/Library/Python/3.8/lib/python/site-packages/pyrogram/session/session.py", line 382, in send
    return await self.send(data, retries - 1, timeout)
  [Previous line repeated 2 more times]
  File "/Users/pavel/Library/Python/3.8/lib/python/site-packages/pyrogram/session/session.py", line 375, in send
    raise e from None
  File "/Users/pavel/Library/Python/3.8/lib/python/site-packages/pyrogram/session/session.py", line 362, in send
    return await self._send(data, timeout=timeout)
  File "/Users/pavel/Library/Python/3.8/lib/python/site-packages/pyrogram/session/session.py", line 327, in _send
    raise TimeoutError
TimeoutError
socket.send() raised exception.
socket.send() raised exception.
Task exception was never retrieved
future: <Task finished name='Task-55161' coro=<Client.handle_updates() done, defined at /Users/pavel/Library/Python/3.8/lib/python/site-packages/pyrogram/client.py:525> exception=OSError(ConnectionResetError('Connection lost'))>
Traceback (most recent call last):
  File "/Users/pavel/Library/Python/3.8/lib/python/site-packages/pyrogram/client.py", line 552, in handle_updates
    diff = await self.send(
  File "/Users/pavel/Library/Python/3.8/lib/python/site-packages/pyrogram/methods/advanced/send.py", line 77, in send
    r = await self.session.send(
  File "/Users/pavel/Library/Python/3.8/lib/python/site-packages/pyrogram/session/session.py", line 382, in send
    return await self.send(data, retries - 1, timeout)
  File "/Users/pavel/Library/Python/3.8/lib/python/site-packages/pyrogram/session/session.py", line 382, in send
    return await self.send(data, retries - 1, timeout)
  File "/Users/pavel/Library/Python/3.8/lib/python/site-packages/pyrogram/session/session.py", line 382, in send
    return await self.send(data, retries - 1, timeout)
  [Previous line repeated 2 more times]
  File "/Users/pavel/Library/Python/3.8/lib/python/site-packages/pyrogram/session/session.py", line 375, in send
    raise e from None
  File "/Users/pavel/Library/Python/3.8/lib/python/site-packages/pyrogram/session/session.py", line 362, in send
    return await self._send(data, timeout=timeout)
  File "/Users/pavel/Library/Python/3.8/lib/python/site-packages/pyrogram/session/session.py", line 316, in _send
    raise e
  File "/Users/pavel/Library/Python/3.8/lib/python/site-packages/pyrogram/session/session.py", line 313, in _send
    await self.connection.send(payload)
  File "/Users/pavel/Library/Python/3.8/lib/python/site-packages/pyrogram/connection/connection.py", line 83, in send
    raise OSError(e)
OSError: Connection lost
socket.send() raised exception.
Task exception was never retrieved
future: <Task finished name='Task-55162' coro=<Client.handle_updates() done, defined at /Users/pavel/Library/Python/3.8/lib/python/site-packages/pyrogram/client.py:525> exception=OSError(ConnectionResetError('Connection lost'))>
Traceback (most recent call last):
  File "/Users/pavel/Library/Python/3.8/lib/python/site-packages/pyrogram/client.py", line 552, in handle_updates
    diff = await self.send(
  File "/Users/pavel/Library/Python/3.8/lib/python/site-packages/pyrogram/methods/advanced/send.py", line 77, in send
    r = await self.session.send(
  File "/Users/pavel/Library/Python/3.8/lib/python/site-packages/pyrogram/session/session.py", line 382, in send
    return await self.send(data, retries - 1, timeout)
  File "/Users/pavel/Library/Python/3.8/lib/python/site-packages/pyrogram/session/session.py", line 382, in send
    return await self.send(data, retries - 1, timeout)
  File "/Users/pavel/Library/Python/3.8/lib/python/site-packages/pyrogram/session/session.py", line 382, in send
    return await self.send(data, retries - 1, timeout)
  [Previous line repeated 2 more times]
  File "/Users/pavel/Library/Python/3.8/lib/python/site-packages/pyrogram/session/session.py", line 375, in send
    raise e from None
  File "/Users/pavel/Library/Python/3.8/lib/python/site-packages/pyrogram/session/session.py", line 362, in send
    return await self._send(data, timeout=timeout)
  File "/Users/pavel/Library/Python/3.8/lib/python/site-packages/pyrogram/session/session.py", line 316, in _send
    raise e
  File "/Users/pavel/Library/Python/3.8/lib/python/site-packages/pyrogram/session/session.py", line 313, in _send
    await self.connection.send(payload)
  File "/Users/pavel/Library/Python/3.8/lib/python/site-packages/pyrogram/connection/connection.py", line 83, in send
    raise OSError(e)
OSError: Connection lost
socket.send() raised exception.
Task exception was never retrieved
future: <Task finished name='Task-55163' coro=<Client.handle_updates() done, defined at /Users/pavel/Library/Python/3.8/lib/python/site-packages/pyrogram/client.py:525> exception=OSError(ConnectionResetError('Connection lost'))>
Traceback (most recent call last):
  File "/Users/pavel/Library/Python/3.8/lib/python/site-packages/pyrogram/client.py", line 552, in handle_updates
    diff = await self.send(
  File "/Users/pavel/Library/Python/3.8/lib/python/site-packages/pyrogram/methods/advanced/send.py", line 77, in send
    r = await self.session.send(
  File "/Users/pavel/Library/Python/3.8/lib/python/site-packages/pyrogram/session/session.py", line 382, in send
    return await self.send(data, retries - 1, timeout)
  File "/Users/pavel/Library/Python/3.8/lib/python/site-packages/pyrogram/session/session.py", line 382, in send
    return await self.send(data, retries - 1, timeout)
  File "/Users/pavel/Library/Python/3.8/lib/python/site-packages/pyrogram/session/session.py", line 382, in send
    return await self.send(data, retries - 1, timeout)
  [Previous line repeated 2 more times]
  File "/Users/pavel/Library/Python/3.8/lib/python/site-packages/pyrogram/session/session.py", line 375, in send
    raise e from None
  File "/Users/pavel/Library/Python/3.8/lib/python/site-packages/pyrogram/session/session.py", line 362, in send
    return await self._send(data, timeout=timeout)
  File "/Users/pavel/Library/Python/3.8/lib/python/site-packages/pyrogram/session/session.py", line 316, in _send
    raise e
  File "/Users/pavel/Library/Python/3.8/lib/python/site-packages/pyrogram/session/session.py", line 313, in _send
    await self.connection.send(payload)
  File "/Users/pavel/Library/Python/3.8/lib/python/site-packages/pyrogram/connection/connection.py", line 83, in send
    raise OSError(e)
OSError: Connection lost
socket.send() raised exception.
socket.send() raised exception.
socket.send() raised exception.
socket.send() raised exception.
socket.send() raised exception.
socket.send() raised exception.
socket.send() raised exception.
defigemsdiscussion
Unable to connect due to network issues: timed out
Unable to connect due to network issues: timed out
Unable to connect due to network issues: timed out
Unable to connect due to network issues: timed out
Connection failed! Trying again...
Unable to connect due to network issues: timed out
Unable to connect due to network issues: timed out
Unable to connect due to network issues: timed out
Unable to connect due to network issues: timed out
Unable to connect due to network issues: timed out
Connection failed! Trying again...
Unable to connect due to network issues: timed out
Connection failed! Trying again...
Unable to connect due to network issues: timed out
Unable to connect due to network issues: timed out
Unable to connect due to network issues: timed out
Telegram says: [403 CHAT_WRITE_FORBIDDEN] - You don't have rights to send messages in this chat (caused by "messages.SendMessage")
shaadi_com
bundleafrica
rotthegame
officalroyalwin
gunstarglobal
Telegram says: [403 CHAT_WRITE_FORBIDDEN] - You don't have rights to send messages in this chat (caused by "messages.SendMessage")
trippyheavenn
seedifyfundofficial
Telegram says: [403 CHAT_WRITE_FORBIDDEN] - You don't have rights to send messages in this chat (caused by "messages.SendMessage")
gcryptochat
amd_discussion
Unable to connect due to network issues: timed out
Unable to connect due to network issues: timed out
Unable to connect due to network issues: timed out
Unable to connect due to network issues: timed out
Unable to connect due to network issues: timed out
Connection failed! Trying again...
metablackout_global
socket.send() raised exception.
socket.send() raised exception.
socket.send() raised exception.
socket.send() raised exception.
socket.send() raised exception.
socket.send() raised exception.
socket.send() raised exception.
Telegram says: [403 CHAT_WRITE_FORBIDDEN] - You don't have rights to send messages in this chat (caused by "messages.SendMessage")
tvs_otc
mouofficialen
Unable to connect due to network issues: timed out
Unable to connect due to network issues: timed out
Unable to connect due to network issues: timed out
Unable to connect due to network issues: timed out
Unable to connect due to network issues: timed out
Connection failed! Trying again...
jiu_cai_yuan
tdisland
Telegram says: [400 USER_NOT_PARTICIPANT] - The user is not a member of this chat (caused by "channels.LeaveChannel")
Telegram says: [403 CHAT_WRITE_FORBIDDEN] - You don't have rights to send messages in this chat (caused by "messages.SendMessage")
cronosworld
blocksport_official
Telegram says: [400 USER_NOT_PARTICIPANT] - The user is not a member of this chat (caused by "channels.LeaveChannel")
gateio
polkabridgegroup
rpgcen
taigaprotocol
Telegram says: [403 CHAT_WRITE_FORBIDDEN] - You don't have rights to send messages in this chat (caused by "messages.SendMessage")

